System check identified some issues:

WARNINGS:
app_test.Syain.job_end: (fields.W122) 'max_length' is ignored when used with IntegerField
	HINT: Remove 'max_length' from field
app_test.Syain.job_start: (fields.W122) 'max_length' is ignored when used with IntegerField
	HINT: Remove 'max_length' from field
app_test.Syain.max: (fields.W122) 'max_length' is ignored when used with IntegerField
	HINT: Remove 'max_length' from field
app_test.Syain.min: (fields.W122) 'max_length' is ignored when used with IntegerField
	HINT: Remove 'max_length' from field
app_test.Syain.overtime: (fields.W122) 'max_length' is ignored when used with IntegerField
	HINT: Remove 'max_length' from field
polls.Syain.job_end: (fields.W122) 'max_length' is ignored when used with IntegerField
	HINT: Remove 'max_length' from field
polls.Syain.job_start: (fields.W122) 'max_length' is ignored when used with IntegerField
	HINT: Remove 'max_length' from field
polls.Syain.max: (fields.W122) 'max_length' is ignored when used with IntegerField
	HINT: Remove 'max_length' from field
polls.Syain.min: (fields.W122) 'max_length' is ignored when used with IntegerField
	HINT: Remove 'max_length' from field
polls.Syain.overtime: (fields.W122) 'max_length' is ignored when used with IntegerField
	HINT: Remove 'max_length' from field

System check identified 10 issues (0 silenced).
[11/Sep/2016 21:46:34] "GET /form_test HTTP/1.1" 200 1567
[11/Sep/2016 21:53:34] "GET /form_test HTTP/1.1" 200 1567
[11/Sep/2016 22:00:47] "GET /form_test HTTP/1.1" 200 1567
Performing system checks...

September 11, 2016 - 21:45:48
Django version 1.9.6, using settings 'test_project.settings'
Starting development server at http://0.0.0.0:8080/
Quit the server with CONTROL-C.
System check identified some issues:

WARNINGS:
app_test.Syain.job_end: (fields.W122) 'max_length' is ignored when used with IntegerField
	HINT: Remove 'max_length' from field
app_test.Syain.job_start: (fields.W122) 'max_length' is ignored when used with IntegerField
	HINT: Remove 'max_length' from field
app_test.Syain.max: (fields.W122) 'max_length' is ignored when used with IntegerField
	HINT: Remove 'max_length' from field
app_test.Syain.min: (fields.W122) 'max_length' is ignored when used with IntegerField
	HINT: Remove 'max_length' from field
app_test.Syain.overtime: (fields.W122) 'max_length' is ignored when used with IntegerField
	HINT: Remove 'max_length' from field
polls.Syain.job_end: (fields.W122) 'max_length' is ignored when used with IntegerField
	HINT: Remove 'max_length' from field
polls.Syain.job_start: (fields.W122) 'max_length' is ignored when used with IntegerField
	HINT: Remove 'max_length' from field
polls.Syain.max: (fields.W122) 'max_length' is ignored when used with IntegerField
	HINT: Remove 'max_length' from field
polls.Syain.min: (fields.W122) 'max_length' is ignored when used with IntegerField
	HINT: Remove 'max_length' from field
polls.Syain.overtime: (fields.W122) 'max_length' is ignored when used with IntegerField
	HINT: Remove 'max_length' from field

System check identified 10 issues (0 silenced).
Performing system checks...

September 11, 2016 - 22:23:01
Django version 1.9.6, using settings 'test_project.settings'
Starting development server at http://0.0.0.0:8080/
Quit the server with CONTROL-C.
Unhandled exception in thread started by <function check_errors.<locals>.wrapper at 0x7f06b25aa378>
Traceback (most recent call last):
  File "/usr/local/lib/python3.4/dist-packages/django/utils/autoreload.py", line 226, in wrapper
    fn(*args, **kwargs)
  File "/usr/local/lib/python3.4/dist-packages/django/core/management/commands/runserver.py", line 116, in inner_run
    self.check(display_num_errors=True)
  File "/usr/local/lib/python3.4/dist-packages/django/core/management/base.py", line 426, in check
    include_deployment_checks=include_deployment_checks,
  File "/usr/local/lib/python3.4/dist-packages/django/core/checks/registry.py", line 75, in run_checks
    new_errors = check(app_configs=app_configs)
  File "/usr/local/lib/python3.4/dist-packages/django/core/checks/urls.py", line 13, in check_url_config
    return check_resolver(resolver)
  File "/usr/local/lib/python3.4/dist-packages/django/core/checks/urls.py", line 23, in check_resolver
    for pattern in resolver.url_patterns:
  File "/usr/local/lib/python3.4/dist-packages/django/utils/functional.py", line 33, in __get__
    res = instance.__dict__[self.name] = self.func(instance)
  File "/usr/local/lib/python3.4/dist-packages/django/core/urlresolvers.py", line 417, in url_patterns
    patterns = getattr(self.urlconf_module, "urlpatterns", self.urlconf_module)
  File "/usr/local/lib/python3.4/dist-packages/django/utils/functional.py", line 33, in __get__
    res = instance.__dict__[self.name] = self.func(instance)
  File "/usr/local/lib/python3.4/dist-packages/django/core/urlresolvers.py", line 410, in urlconf_module
    return import_module(self.urlconf_name)
  File "/usr/lib/python3.4/importlib/__init__.py", line 109, in import_module
    return _bootstrap._gcd_import(name[level:], package, level)
  File "<frozen importlib._bootstrap>", line 2254, in _gcd_import
  File "<frozen importlib._bootstrap>", line 2237, in _find_and_load
  File "<frozen importlib._bootstrap>", line 2226, in _find_and_load_unlocked
  File "<frozen importlib._bootstrap>", line 1200, in _load_unlocked
  File "<frozen importlib._bootstrap>", line 1129, in _exec
  File "<frozen importlib._bootstrap>", line 1471, in exec_module
  File "<frozen importlib._bootstrap>", line 321, in _call_with_frames_removed
  File "/home/ubuntu/workspace/test_project/test_project/urls.py", line 18, in <module>
    import polls.views as views_polls
  File "/home/ubuntu/workspace/test_project/polls/views.py", line 3, in <module>
    from .models import SyainData
ImportError: cannot import name 'SyainData'
Performing system checks...

System check identified some issues:

WARNINGS:
app_test.Syain.job_end: (fields.W122) 'max_length' is ignored when used with IntegerField
	HINT: Remove 'max_length' from field
app_test.Syain.job_start: (fields.W122) 'max_length' is ignored when used with IntegerField
	HINT: Remove 'max_length' from field
app_test.Syain.max: (fields.W122) 'max_length' is ignored when used with IntegerField
	HINT: Remove 'max_length' from field
app_test.Syain.min: (fields.W122) 'max_length' is ignored when used with IntegerField
	HINT: Remove 'max_length' from field
app_test.Syain.overtime: (fields.W122) 'max_length' is ignored when used with IntegerField
	HINT: Remove 'max_length' from field
polls.SyainData.job_end: (fields.W122) 'max_length' is ignored when used with IntegerField
	HINT: Remove 'max_length' from field
polls.SyainData.job_start: (fields.W122) 'max_length' is ignored when used with IntegerField
	HINT: Remove 'max_length' from field
polls.SyainData.max: (fields.W122) 'max_length' is ignored when used with IntegerField
	HINT: Remove 'max_length' from field
polls.SyainData.min: (fields.W122) 'max_length' is ignored when used with IntegerField
	HINT: Remove 'max_length' from field
polls.SyainData.overtime: (fields.W122) 'max_length' is ignored when used with IntegerField
	HINT: Remove 'max_length' from field

System check identified 10 issues (0 silenced).
Performing system checks...

September 11, 2016 - 22:26:52
Django version 1.9.6, using settings 'test_project.settings'
Starting development server at http://0.0.0.0:8080/
Quit the server with CONTROL-C.
Unhandled exception in thread started by <function check_errors.<locals>.wrapper at 0x7f937abb0378>
Traceback (most recent call last):
  File "/usr/local/lib/python3.4/dist-packages/django/utils/autoreload.py", line 226, in wrapper
    fn(*args, **kwargs)
  File "/usr/local/lib/python3.4/dist-packages/django/core/management/commands/runserver.py", line 116, in inner_run
    self.check(display_num_errors=True)
  File "/usr/local/lib/python3.4/dist-packages/django/core/management/base.py", line 426, in check
    include_deployment_checks=include_deployment_checks,
  File "/usr/local/lib/python3.4/dist-packages/django/core/checks/registry.py", line 75, in run_checks
    new_errors = check(app_configs=app_configs)
  File "/usr/local/lib/python3.4/dist-packages/django/core/checks/urls.py", line 13, in check_url_config
    return check_resolver(resolver)
  File "/usr/local/lib/python3.4/dist-packages/django/core/checks/urls.py", line 23, in check_resolver
    for pattern in resolver.url_patterns:
  File "/usr/local/lib/python3.4/dist-packages/django/utils/functional.py", line 33, in __get__
    res = instance.__dict__[self.name] = self.func(instance)
  File "/usr/local/lib/python3.4/dist-packages/django/core/urlresolvers.py", line 417, in url_patterns
    patterns = getattr(self.urlconf_module, "urlpatterns", self.urlconf_module)
  File "/usr/local/lib/python3.4/dist-packages/django/utils/functional.py", line 33, in __get__
    res = instance.__dict__[self.name] = self.func(instance)
  File "/usr/local/lib/python3.4/dist-packages/django/core/urlresolvers.py", line 410, in urlconf_module
    return import_module(self.urlconf_name)
  File "/usr/lib/python3.4/importlib/__init__.py", line 109, in import_module
    return _bootstrap._gcd_import(name[level:], package, level)
  File "<frozen importlib._bootstrap>", line 2254, in _gcd_import
  File "<frozen importlib._bootstrap>", line 2237, in _find_and_load
  File "<frozen importlib._bootstrap>", line 2226, in _find_and_load_unlocked
  File "<frozen importlib._bootstrap>", line 1200, in _load_unlocked
  File "<frozen importlib._bootstrap>", line 1129, in _exec
  File "<frozen importlib._bootstrap>", line 1471, in exec_module
  File "<frozen importlib._bootstrap>", line 321, in _call_with_frames_removed
  File "/home/ubuntu/workspace/test_project/test_project/urls.py", line 18, in <module>
    import polls.views as views_polls
  File "/home/ubuntu/workspace/test_project/polls/views.py", line 3, in <module>
    from models import SyainData
ImportError: No module named 'models'
Performing system checks...

System check identified some issues:

WARNINGS:
app_test.Syain.job_end: (fields.W122) 'max_length' is ignored when used with IntegerField
	HINT: Remove 'max_length' from field
app_test.Syain.job_start: (fields.W122) 'max_length' is ignored when used with IntegerField
	HINT: Remove 'max_length' from field
app_test.Syain.max: (fields.W122) 'max_length' is ignored when used with IntegerField
	HINT: Remove 'max_length' from field
app_test.Syain.min: (fields.W122) 'max_length' is ignored when used with IntegerField
	HINT: Remove 'max_length' from field
app_test.Syain.overtime: (fields.W122) 'max_length' is ignored when used with IntegerField
	HINT: Remove 'max_length' from field
polls.SyainData.job_end: (fields.W122) 'max_length' is ignored when used with IntegerField
	HINT: Remove 'max_length' from field
polls.SyainData.job_start: (fields.W122) 'max_length' is ignored when used with IntegerField
	HINT: Remove 'max_length' from field
polls.SyainData.max: (fields.W122) 'max_length' is ignored when used with IntegerField
	HINT: Remove 'max_length' from field
polls.SyainData.min: (fields.W122) 'max_length' is ignored when used with IntegerField
	HINT: Remove 'max_length' from field
polls.SyainData.overtime: (fields.W122) 'max_length' is ignored when used with IntegerField
	HINT: Remove 'max_length' from field

System check identified 10 issues (0 silenced).
Performing system checks...

September 11, 2016 - 22:27:24
Django version 1.9.6, using settings 'test_project.settings'
Starting development server at http://0.0.0.0:8080/
Quit the server with CONTROL-C.
Unhandled exception in thread started by <function check_errors.<locals>.wrapper at 0x7f34813e9378>
Traceback (most recent call last):
  File "/usr/local/lib/python3.4/dist-packages/django/utils/autoreload.py", line 226, in wrapper
    fn(*args, **kwargs)
  File "/usr/local/lib/python3.4/dist-packages/django/core/management/commands/runserver.py", line 116, in inner_run
    self.check(display_num_errors=True)
  File "/usr/local/lib/python3.4/dist-packages/django/core/management/base.py", line 472, in check
    raise SystemCheckError(msg)
django.core.management.base.SystemCheckError: SystemCheckError: System check identified some issues:

ERRORS:
polls.SyainData.corporation_name: (fields.E120) CharFields must define a 'max_length' attribute.
polls.SyainData.name: (fields.E120) CharFields must define a 'max_length' attribute.
polls.SyainData.phone: (fields.E120) CharFields must define a 'max_length' attribute.

WARNINGS:
app_test.Syain.job_end: (fields.W122) 'max_length' is ignored when used with IntegerField
	HINT: Remove 'max_length' from field
app_test.Syain.job_start: (fields.W122) 'max_length' is ignored when used with IntegerField
	HINT: Remove 'max_length' from field
app_test.Syain.max: (fields.W122) 'max_length' is ignored when used with IntegerField
	HINT: Remove 'max_length' from field
app_test.Syain.min: (fields.W122) 'max_length' is ignored when used with IntegerField
	HINT: Remove 'max_length' from field
app_test.Syain.overtime: (fields.W122) 'max_length' is ignored when used with IntegerField
	HINT: Remove 'max_length' from field

System check identified 8 issues (0 silenced).
Performing system checks...

System check identified some issues:

WARNINGS:
app_test.Syain.job_end: (fields.W122) 'max_length' is ignored when used with IntegerField
	HINT: Remove 'max_length' from field
app_test.Syain.job_start: (fields.W122) 'max_length' is ignored when used with IntegerField
	HINT: Remove 'max_length' from field
app_test.Syain.max: (fields.W122) 'max_length' is ignored when used with IntegerField
	HINT: Remove 'max_length' from field
app_test.Syain.min: (fields.W122) 'max_length' is ignored when used with IntegerField
	HINT: Remove 'max_length' from field
app_test.Syain.overtime: (fields.W122) 'max_length' is ignored when used with IntegerField
	HINT: Remove 'max_length' from field
polls.SyainData.overtime: (fields.W122) 'max_length' is ignored when used with IntegerField
	HINT: Remove 'max_length' from field

System check identified 6 issues (0 silenced).
Performing system checks...


You have unapplied migrations; your app may not work properly until they are applied.
Run 'python manage.py migrate' to apply them.
September 11, 2016 - 22:29:02
Django version 1.9.6, using settings 'test_project.settings'
Starting development server at http://0.0.0.0:8080/
Quit the server with CONTROL-C.
Performing system checks...

System check identified no issues (0 silenced).
September 11, 2016 - 23:33:27
Django version 1.9.6, using settings 'test_project.settings'
Starting development server at http://0.0.0.0:8080/
Quit the server with CONTROL-C.
[12/Sep/2016 02:14:22] "GET /form_test HTTP/1.1" 200 1963
Not Found: /favicon.ico
